Workbook

Sheet START HERE
A1: Control | B1: Current disposition
A2: Issue | B2: P14 Rev0 |25October2026 | Consolidated management-development package
A3: Baseline status | B3: NOT APPROVED; no actual NOA/progress/capacity or funding independently established
A4: Latest batch | B4: 68 supplied;67 opened;52 distinct contents;7 distinct contents without prior local hash match
A5: Transfer exception | B5: SHIVANSH ONGC Offshore Bridges - PRELIMINARY.pdf exceeds32MiB; not reviewed
A6: Prior batch | B6: P13:76 opened;21 distinct; XML207tasks/124links screened
A7: Authoritative use | B7: Management requirements/registers implemented here; technical design, actual execution and external approvals require their evidence
A8: Planning scenario | B8: 285activities,1Nov2026 assumed start; base finish6Apr2028, not an approved forecast
A9: Scenario meaning | B9: Explicit named resource sequencing; office/yard/offshore calendars; unverified engineering/productivity/supply inputs
A10: Financial use | B10: Blank inputs mean missing; no completed funding or EAC claim
A11: Source controls | B11: P8–P13 remain source evidence; P14 is consolidated management index and scenario, not a superseding contract
A12: Progress | B12: No actual work performed inferred from planning spreadsheets
A13: Revision | B13: Preserve uploaded originals; update P14 under change control

Sheet CEO Decisions
A1: Priority | B1: Decision | C1: Owner | D1: Required evidence | E1: Trigger | F1: Status
A2: P1 | B2: Confirm NOA/start, governing SCC/A3 and applicability | C2: Contracts | D2: Controlled issue list and actual award | E2: Before baseline | F2: OPEN
A3: P1 | B3: Freeze bridge scope and resolve MTO/bearing/load conflicts | C3: Engineering | D3: Survey, corrected MTO and design queries | E3: Before affected PO/AFC | F3: OPEN
A4: P1 | B4: Validate target feasibility and seasonal strategy | C4: Project Director | D4: Approved dates, capacity and supplier/vessel offers | E4: Before completion commitment | F4: OPEN
A5: P1 | B5: Fund full execution and commercial exposure | C5: Finance | D5: Priced estimate, term sheet and cash stress | E5: Before commitments | F5: OPEN
A6: P1 | B6: Nominate and verify delivery capacity | C6: Project Director | D6: People, design teams, fabrication/NDT/coating and marine commitments | E6: Before mobilisation | F6: OPEN
A7: P1 | B7: Approve stage-specific design/marine assurance | C7: Engineering/Marine | D7: Independent checked calculations and accepted procedures | E7: Before field release | F7: OPEN
A8: P2 | B8: Adopt progress/e-MB and completion boundaries | C8: Controls | D8: Contract weights, signed rules and turnover matrix | E8: Before first progress claim | F8: OPEN
A9: P2 | B9: Resolve large-file transfer exception | C9: Document Control | D9: Readable split PDF or equivalent verified source | E9: Before claiming complete source review | F9: OPEN

Sheet A-Z Execution Plan
A1: Code | B1: Workstream | C1: Accountable role | D1: Inputs | E1: Required procedure | F1: Acceptance evidence | G1: Control measure | H1: Source
A2: A | B2: Accountability and authority | C2: Project Director | D2: NOA/contract, scope split and corporate delegation | E2: Appoint named managers and deputies; record availability and competing commitments; establish RACI; set spending/change/technical-release authority; chair weekly integration review. | F2: Signed organisation/RACI and delegated-authority register | G2: Named accountable owner for each control; no unidentified release authority | H2: SCC1; Technical BEC5.2–5.4
A3: B | B3: Baseline and requirements | C3: Contracts Manager | D3: Tender, addenda/corrigenda, source drawing register | E3: Maintain clause-to-deliverable matrix; resolve SCC/GCC precedence using B-4; link revisions and deletions; isolate S&SRP references; freeze controlled scope by bridge and retain open discrepancies. | F3: Approved requirements and scope baseline; assumption/change log | G3: Every requirement has source, owner, verification and disposition | H3: P8–P12; CQ replies; B-4
A4: C | B4: Contract, qualification and compliance | C4: Contracts Manager | D4: Actual bidding route, experience evidence and amendments | E4: Check110MT/marine route and consortium exceptions; retain PM/qualifying main activity; obtain subcontract commitments; verify TPI authentication and valid accreditation; reconcile financial evidence; manage securities and integrity-pact disclosures. | F4: Qualification/compliance matrix and evidence bundle | G4: No unsupported bidder confirmations or expired verification evidence | H4: Technical BEC5; P9/P11
A5: D | B5: Design basis and survey | C5: Engineering Manager | D5: BRRP criteria, tender GAs and survey access | E5: Verify coordinates, elevations, spans, clearances, member sizes/thickness/loss, support movement, piping/cable loads and NDT; create controlled datums; close bearing/camber/load discrepancies; record later company instructions under change control. | F5: Accepted survey dossier and bridge-specific design basis | G5: Survey-derived geometry and load status visible on every engineering package | H5: CriteriaPartII; Corrigendum3 GCC2.3.6
A6: E | B6: Engineering and independent checking | C6: Engineering Manager | D6: Accepted survey, criteria, scope and discipline interfaces | E6: Analyse bridge and supporting platforms, members/joints, bearings, fatigue/VIV, preservice lifts/transport and temporary stages; iterate piping reactions; detail connections; perform independent check and comment closure; submit through controlled DCI. | F6: Checked calculations, interface reactions, design reports and accepted drawings | G6: No source-study utilisation ratio represented as new design proof | H6: C8; Combined1Annexure1; DesignCriteria
A7: F | B7: Fabrication drawings and AFC release | C7: Lead Structural Engineer | D7: Accepted mother analysis and verified geometry | E7: Issue source-to-detail mapping, shop GAs, member/cut lists, joint/weld maps, bearing/guides, padeyes/supports and temporary-stability details; apply source revisions and CRS; independent check then company/CA release as applicable. | F7: Signed bridge-specific release index with matching drawing/MTO/procedure revisions | G7: AFC status requires actual authorised approval and field-copy control | H7: C8 mother documents; Combined1 pp27–41
A8: G | B8: Geometry, MTO and weight control | C8: Quantity/Weight Engineer | D8: Released model/drawings and field verification | E8: Separate new bridge, strengthening, new landing, existing landing, demolition and finish quantities; resolve1MT/2m/1m² discrepancies; calculate member-length/plate/bolt/weld/coating MTO and wastage explicitly; track module dry/wet/rigging weights and COG. | F8: Traceable MTO revisions, reconciliation and verified module weight report | G8: No bulk tonnage substituted for lift weight, member BOM or coating area | H8: SOW quantity table; MTOIRT; Criteria weight/COG trigger
A9: H | B9: HSE and SIMOPS | C9: HSE Manager | D9: Workfront hazards, operating platform and vessel requirements | E9: Complete HIRA/JSA/PTW, isolation/LOTO, hot work, gas testing, work-at-height/rescue, dropped objects, scaffold/access, marine transfers, occupational exposure and emergency interfaces; train staff; issue certified PPE and validate work-start clearance. | F9: Approved HSE/SIMOPS plan, personnel matrix and permit packs | G9: Zero work starts without applicable permits, isolation and readiness evidence | H9: SCC7/8; PPElist; OISD155 applicability
A10: I | B10: Interface and operations management | C10: Interface Manager | D10: Platform operations, engineering and contractors | E10: Register structural/piping/electrical/instrument/telecom/firewater interfaces; agree outage and transfer sequence; assign tie-in owners; confirm access and emergency routes; track support reactions and dimensional tolerances; resolve NQO/NOQ naming. | F10: Signed interface agreements, outage windows and battery-limit register | G10: No unowned interface on lookahead or lift plan | H10: SCC1.7; Combined1/2/3
A11: J | B11: Joint inspections and quality assurance | C11: QA/QC Manager | D11: Project quality plan, codes, specifications and approved ITP | E11: Set inspection/hold/witness points; qualify welding and personnel; control heat/consumable traceability; calibrate instruments; inspect fit-up/weld/NDT/coating/dimensions; repair and close NCRs; issue releases and indexed records. | F11: ITP, qualification dossiers, inspection releases and NCR closure | G11: No concealed work or next-stage release through an unresolved hold point | H11: FS2009F; FS2005Rev9; C8
A12: K | B12: Key suppliers and procurement | C12: Procurement Manager | D12: Approved requisition, MTO, PS and compliant sources | E12: Package25 procurement scopes; RFQ and technical/commercial evaluation; verify SVL12.3 status/product/location, steel melt/pour/DVA and traceability; obtain PS approvals, place authorised PO, expedite and inspect; preserve vendor-data dependencies. | F12: PO/delivery/inspection register with quoted dates and evidence | G12: No unpriced allowance treated as commitment; no silent substitution | H12: SVL12.3 Combined3 pp261–341; Corr3; C8
... A27: Z | B27: Warranty, final account and lessons | C27: Project Director | D27: Acceptance terms, outstanding obligations and final payments | E27: Track defect liability/warranty and insurance/security releases; resolve claims and subcontract final accounts; retain integrity-pact/record obligations; archive controlled native/PDF data and access; close lessons and verify promised performance against outcomes. | F27: Contract closure certificate, release schedule and retained records | G27: Physical completion, financial closure and obligation expiry are separate dates | H27: IntegrityPact9; GCC/SCC governing periods

Sheet Source Coverage
A1: File | B1: SHA256 | C1: Prior exact matches | D1: Duplicate in batch | E1: Review disposition | F1: Local source
A2: Addendum.pdf | B2: 1742ad4dd672858b1ee148ba6e82b5d4594b3205a8db344d7631408e582a26fb | C2: 5 | E2: Hash/open checked; prior review reused | F2: /workspace/attachments/71d9446a-9284-4152-923c-f5c85a23c0f1/Addendum.pdf
A3: Addendum (1).pdf | B3: 1742ad4dd672858b1ee148ba6e82b5d4594b3205a8db344d7631408e582a26fb | C3: 5 | D3: Addendum.pdf | E3: Hash/open checked; prior review reused | F3: /workspace/attachments/62e4fd39-6c8f-4f77-88c2-7fbc71905567/Addendum (1).pdf
A4: Addendum_Structure_SOW.pdf | B4: 9720ca8546c67ef9cc4f44a8b4fb480de23da3eed38a6ca5dae2879de8c1485a | C4: 4 | E4: Hash/open checked; prior review reused | F4: /workspace/attachments/652f34f3-904c-4733-84f5-3badb6e94c6e/Addendum_Structure_SOW.pdf
A5: AddendumtoA3.pdf | B5: 191ca9ccafb391c57652a1e4b5831484c2a53765cf6d813b8bdc87dc1de3ce07 | C5: 2 | E5: Hash/open checked; prior review reused | F5: /workspace/attachments/b9a9de3b-b77d-49f1-8ff1-a0c7d55ca00b/AddendumtoA3.pdf
A6: Appendix A-9.pdf | B6: fea757b0e53dd170dbe9c645a10ddfe62eec08e2cfe6f151bbd0adf0bd4ed5e4 | C6: 2 | E6: Hash/open checked; prior review reused | F6: /workspace/attachments/67595e2c-856c-401e-833f-825f1401ae1e/Appendix A-9.pdf
A7: Appendix A-16 List of Agencies.pdf | B7: 09a642f2eb6a23c02a735be3d51b57db316f4d5697aff8e1db8c1ee7bacaa50a | C7: 2 | E7: Hash/open checked; prior review reused | F7: /workspace/attachments/2d2bfd9d-58b4-45b5-9b23-013e947fac6f/Appendix A-16 List of Agencies.pdf
A8: Appendix A-17.pdf | B8: 5d5cde215d0959b2e8126df4a2daf7edb4f91a7fc428146dda9d905c4aad6d6a | C8: 2 | E8: Hash/open checked; prior review reused | F8: /workspace/attachments/0cc90703-59ca-4d42-87f6-a21665d44d80/Appendix A-17.pdf
A9: Appendix A-11 Offshore SVL Revision 12.1.pdf | B9: 86d3ab9001388087d63075d5cde421a51a6d1f4c5857fda8e18f7459637f5381 | C9: 2 | E9: Hash/open checked; prior review reused | F9: /workspace/attachments/53ebe58d-28b5-4afe-a534-d4e5e90c0768/Appendix A-11 Offshore SVL Revision 12.1.pdf
A10: Appendix B-5.pdf | B10: 82222c4cdca2f142d619e139280c264c68085cca7444ad0f1152204a91f1bf3e | C10: 3 | E10: Hash/open checked; prior review reused | F10: /workspace/attachments/0f6b6e5d-3512-48b3-b967-7e0b5e54488c/Appendix B-5.pdf
A11: Appendix B-6.pdf | B11: dd4ce8688af1b3976c4fc752c9a19e4e14d43984c0e25733d11c6703d9919858 | C11: 2 | E11: Hash/open checked; prior review reused | F11: /workspace/attachments/4bee04c0-bc1c-43e2-9067-bf305f40553e/Appendix B-6.pdf
A12: Appendix C-9.pdf | B12: f20a85ca3a13c08e62bb18a41838d9e32910cd4f0d7c6b0ab0623df4ca9aeec5 | C12: 2 | E12: Hash/open checked; prior review reused | F12: /workspace/attachments/253ac71f-d176-432c-911f-60a8f984d59d/Appendix C-9.pdf
A13: Appendix C-8 DCI MCI.pdf | B13: 086b2f7837d09bc6320e2e0794f5b73fc7788b2cb9ecb5a08fa76836e2c97944 | C13: 2 | E13: Hash/open checked; prior review reused | F13: /workspace/attachments/5e260e43-5134-4a2f-a8df-817300abf68d/Appendix C-8 DCI MCI.pdf
A14: Appendix C-10.pdf | B14: 8f0b1be35e96cc0e953e8614b751f08a987dca4a9060c54319b231f113d7d2d7 | C14: 2 | E14: Hash/open checked; prior review reused | F14: /workspace/attachments/0c0ae9b7-787b-400e-bb17-d6a1c1a58cb8/Appendix C-10.pdf
A15: chart.pdf | B15: 30e8cf255d41edc9930b28ee4a2bea2c82dcd033222333c9a5e914ba0cb16b00 | C15: 0 | E15: Distinct content screened; discipline detail still required | F15: /workspace/attachments/790dcc2a-429d-42e1-9aa9-b5fc913b3310/chart.pdf
... A18: Corrigendum.pdf | B18: 02142550f5d609a6a2ffe4ed64d441eaa00540663cee661ed318446e6e19dea6 | C18: 1 | E18: Hash/open checked; prior review reused | F18: /workspace/attachments/a569298e-9b51-4a0a-865f-1a4350827b47/Corrigendum.pdf
A19: Combined_Addendum_1.pdf | B19: dfda0877c74c0745763a6d8eb0e8894014d27b22ec72c8f44955c933cadf1d65 | C19: 4 | D19: Combined_Addendum_1 (1).pdf | E19: Hash/open checked; prior review reused | F19: /workspace/attachments/24075e12-e392-4681-ac05-3e4aa60baea8/Combined_Addendum_1.pdf
A20: Corrigendum_1_BRRP.pdf | B20: 54977537e10a8249587ad2965eca04a057eaa45f932e6a229959bc3fa30ab7c4 | C20: 1 | E20: Hash/open checked; prior review reused | F20: /workspace/attachments/ce432d19-ef2c-4984-9b8f-1061008c14af/Corrigendum_1_BRRP.pdf
A21: Corrigendum_2.pdf | B21: cb996ec5837ec4dcfab1a55e4ffcb56248919a73d70cd53492d64d39a2a7b435 | C21: 1 | E21: Hash/open checked; prior review reused | F21: /workspace/attachments/6f519900-18e2-4842-a3a4-47eab8f9279c/Corrigendum_2.pdf
A22: Corrigendum_3.pdf | B22: e8a07f4059dcb9b81c1cc45b2ae60154c0c142999955b347d2c60133619656d7 | C22: 1 | E22: Hash/open checked; prior review reused | F22: /workspace/attachments/7932c206-c79d-4425-99a1-c83f9e788608/Corrigendum_3.pdf
A23: Corrigendum_4.pdf | B23: 623614acba28baadc68c22229c039399e9b4385c0945b787197b2dedaaa4acf4 | C23: 1 | E23: Hash/open checked; prior review reused | F23: /workspace/attachments/e3752b17-cf9c-472e-a3f1-cdcfb97319d9/Corrigendum_4.pdf
A24: CQ_replies_BRRP.pdf | B24: b006f3d20e7ae10d9800b1b9fabfb3104091b09878fcd6bb83b2f328e926df4a | C24: 1 | E24: Hash/open checked; prior review reused | F24: /workspace/attachments/dfc717ae-169c-4f98-a676-e4f9135968bb/CQ_replies_BRRP.pdf
A25: IP (1).pdf | B25: 8692fb4bca724408df3fe1ec8377faa678e6238f3fe14bb55fbc6ca4b8cdcf50 | C25: 2 | E25: Hash/open checked; prior review reused | F25: /workspace/attachments/86b20843-c858-4bbc-ba34-1eb21ae00511/IP (1).pdf
A26: Combined_Addendum_3.pdf | B26: 6d6369b880718f0b84da0776adc723d99eae59b591c8b5d45f1f0b2596b9d5b6 | C26: 1 | E26: Hash/open checked; prior review reused | F26: /workspace/attachments/1bc81107-8f35-4cbf-9221-83ba100de6ba/Combined_Addendum_3.pdf
A27: Design Criteria & Execution Methodology.pdf | B27: 179b05dabdb90971b5132d38f2a1aa755ce091b640b4e844fa7b0c9cc4a7e706 | C27: 2 | E27: Hash/open checked; prior review reused | F27: /workspace/attachments/88e427dd-3a5a-4b8d-bdbd-b42e46560820/Design Criteria & Execution Methodology.pdf
A28: IP.pdf | B28: 8692fb4bca724408df3fe1ec8377faa678e6238f3fe14bb55fbc6ca4b8cdcf50 | C28: 2 | D28: IP (1).pdf | E28: Hash/open checked; prior review reused | F28: /workspace/attachments/e09fff9b-4787-43dc-9837-32803d295090/IP.pdf
A29: Kits PPE List-BRRP.pdf | B29: 44e2e5f2214d741c15380702504a73ae00076ab5954bb6ce96011a1e06aed841 | C29: 1 | E29: Hash/open checked; prior review reused | F29: /workspace/attachments/fd490052-5a1c-457b-8b21-f994277ea8ec/Kits PPE List-BRRP.pdf
A30: Section 1.pdf | B30: 4396fb90c823805128145920d1348e69942a65e501773d80457a3b671e0f3641 | C30: 1 | E30: Hash/open checked; prior review reused | F30: /workspace/attachments/8da610f6-1801-4fe3-823d-e61a9d261607/Section 1.pdf
A31: Section 2.pdf | B31: 1d6c9da72ce45156e95586056c6d96a06da9563a9a27817dc77935d6fa470a7f | C31: 2 | E31: Hash/open checked; prior review reused | F31: /workspace/attachments/42bc04a5-aa70-4b68-8f62-6aa20791774b/Section 2.pdf
A32: MTO Drawings IRT.pdf | B32: 0a8a008d8bc139d05c75f83c52ba23d637c1f78926b7a19e4007297ac52485cb | C32: 1 | E32: Hash/open checked; prior review reused | F32: /workspace/attachments/6ac405c9-4cf3-4694-b74c-4bf32ee762e0/MTO Drawings IRT.pdf
A33: SHIVANSH ONGC Offshore Bridges - PRELIMINARY.xlsx | B33: caba714d2cc9b32ddf723228a57797a6e588463c0554ced81701982fcd7f7f20 | C33: 2 | E33: Hash/open checked; prior review reused | F33: /workspace/attachments/d9e9d456-d843-439f-9b8b-ba2073e00690/SHIVANSH ONGC Offshore Bridges - PRELIMINARY.xlsx
A34: SHIVANSH_360_Day_EPC_Scheduling_Control_Workbook.xlsx | B34: a4545c34bc3bfdf771c5918e9335e6b288626e024a5f517e4eb0ca7f6fe870ee | C34: 2 | E34: Hash/open checked; prior review reused | F34: /workspace/attachments/9d725d18-b225-48ae-b2c7-08bfdae07e20/SHIVANSH_360_Day_EPC_Scheduling_Control_Workbook.xlsx
A35: Shivansh_BRRPP_Integrated_Execution_Control.xlsx | B35: 2c64809e2cbab409c9897e19ee5b46768287708a1adb9f923457d03177f24c36 | C35: 2 | E35: Hash/open checked; prior review reused | F35: /workspace/attachments/e26488ad-6288-488e-9a57-e805e58d373d/Shivansh_BRRPP_Integrated_Execution_Control.xlsx
A36: Section 3.pdf | B36: 64146db7c46ea30fc3e5161cea2ce94bdb3435e4aefe05a81cfac0174c141108 | C36: 2 | E36: Hash/open checked; prior review reused | F36: /workspace/attachments/e8998ddd-f666-4184-8a06-cfe98fcee70d/Section 3.pdf
A37: Shivansh_BRRPP_Level3_P6_Preparation.xlsx | B37: 186a4f446d7691b5c726f32e8600482c7abde182ef9bbc7d11c07729e4706074 | C37: 2 | E37: Hash/open checked; prior review reused | F37: /workspace/attachments/5cd8d5fa-208f-4c83-8634-cc48ce45f232/Shivansh_BRRPP_Level3_P6_Preparation.xlsx
A38: Shivansh_BRRPP_P6_Activity_Import.csv | B38: cd3865f25e6d42bccc800bd4344e38816fdcf68c6dbbe63c26a0e76096f358d7 | C38: 1 | E38: Hash/open checked; prior review reused | F38: /workspace/attachments/93fa0f79-840c-4179-a70c-0453a58a772a/Shivansh_BRRPP_P6_Activity_Import.csv
A39: Shivansh_BRRPP_Stage4_Resource_Cost_Marine_Planning.xlsx | B39: 88adcd75ff58317d0215801c0cee35b3f8aa03b024e8acbd45382e8138db56f0 | C39: 1 | E39: Hash/open checked; prior review reused | F39: /workspace/attachments/7dc15993-36a3-4025-9400-43b50a6634fa/Shivansh_BRRPP_Stage4_Resource_Cost_Marine_Planning.xlsx
A40: Shivansh_BRRPP_Stage5_Integrated_Marine_Yard_Cost_P6.xlsx | B40: ac85c7dec0f9db25e971b0795623e465a92732bcc873ba6234bd21f485cc2036 | C40: 1 | E40: Hash/open checked; prior review reused | F40: /workspace/attachments/d26e8648-ae53-4e11-9b9e-462a8c2d2bf2/Shivansh_BRRPP_Stage5_Integrated_Marine_Yard_Cost_P6.xlsx
A41: Shivansh_BRRPP_Stage10_Resource_Feasibility (1).xlsx | B41: 44df6c84070a16804ad83487e7575ba1e99569a53e267c8e3da83ac9cfd59621 | C41: 3 | E41: Hash/open checked; prior review reused | F41: /workspace/attachments/eb12ce0c-0f11-4e8b-8f79-44bee2a5c743/Shivansh_BRRPP_Stage10_Resource_Feasibility (1).xlsx
A42: Shivansh_BRRPP_Stage10_Resource_Feasibility.xlsx | B42: 44df6c84070a16804ad83487e7575ba1e99569a53e267c8e3da83ac9cfd59621 | C42: 3 | D42: Shivansh_BRRPP_Stage10_Resource_Feasibility (1).xlsx | E42: Hash/open checked; prior review reused | F42: /workspace/attachments/af8b4024-34f5-445c-bf5a-6a9bdfb92b31/Shivansh_BRRPP_Stage10_Resource_Feasibility.xlsx
...

Sheet Earlier P13 Coverage
A1: File | B1: SHA256 | C1: Prior exact matches | D1: Duplicate | E1: Disposition
A2: SHIVANSH_EPC_Master_Plan_Volume_5 - Copy - Copy - Copy.docx | B2: 780b6b86fcd5d34d71bf2cc18548d62a298cee1a296ad7636365ee10c2ff9226 | C2: 0 | E2: Duplicate comparison; P13 content/XML screening
A3: SHIVANSH_EPC_Master_Plan_Volume_4.docx | B3: fdbbcaf61b89b33696bc164ebf7c866c81f4cac5d9ee8bda20b38c00087f038f | C3: 0 | E3: Duplicate comparison; P13 content/XML screening
A4: SHIVANSH_EPC_Master_Plan_Volume_4 - Copy.docx | B4: fdbbcaf61b89b33696bc164ebf7c866c81f4cac5d9ee8bda20b38c00087f038f | C4: 0 | D4: SHIVANSH_EPC_Master_Plan_Volume_4.docx | E4: Duplicate comparison; P13 content/XML screening
A5: SHIVANSH_EPC_Master_Plan_Volume_5 - Copy (2).docx | B5: 780b6b86fcd5d34d71bf2cc18548d62a298cee1a296ad7636365ee10c2ff9226 | C5: 0 | D5: SHIVANSH_EPC_Master_Plan_Volume_5 - Copy - Copy - Copy.docx | E5: Duplicate comparison; P13 content/XML screening
A6: SHIVANSH_EPC_Master_Plan_Volume_5 - Copy - Copy.docx | B6: 780b6b86fcd5d34d71bf2cc18548d62a298cee1a296ad7636365ee10c2ff9226 | C6: 0 | D6: SHIVANSH_EPC_Master_Plan_Volume_5 - Copy - Copy - Copy.docx | E6: Duplicate comparison; P13 content/XML screening
A7: SHIVANSH_EPC_Master_Plan_Volume_5 - Copy (2) - Copy.docx | B7: 780b6b86fcd5d34d71bf2cc18548d62a298cee1a296ad7636365ee10c2ff9226 | C7: 0 | D7: SHIVANSH_EPC_Master_Plan_Volume_5 - Copy - Copy - Copy.docx | E7: Duplicate comparison; P13 content/XML screening
A8: SHIVANSH_EPC_Master_Plan_Volume_5 - Copy.docx | B8: 780b6b86fcd5d34d71bf2cc18548d62a298cee1a296ad7636365ee10c2ff9226 | C8: 0 | D8: SHIVANSH_EPC_Master_Plan_Volume_5 - Copy - Copy - Copy.docx | E8: Duplicate comparison; P13 content/XML screening
A9: SHIVANSH_EPC_Master_Plan_Volume_5.docx | B9: 780b6b86fcd5d34d71bf2cc18548d62a298cee1a296ad7636365ee10c2ff9226 | C9: 0 | D9: SHIVANSH_EPC_Master_Plan_Volume_5 - Copy - Copy - Copy.docx | E9: Duplicate comparison; P13 content/XML screening
A10: SHIVANSH_EPC_Master_Plan_Volume_6 - Copy - Copy.docx | B10: 210c62c17a32f6b0545c512e9ae7d145c318845c51edd1ab2af106cd7ba3d79e | C10: 0 | E10: Duplicate comparison; P13 content/XML screening
A11: SHIVANSH_EPC_Master_Plan_Volume_6.docx | B11: 210c62c17a32f6b0545c512e9ae7d145c318845c51edd1ab2af106cd7ba3d79e | C11: 0 | D11: SHIVANSH_EPC_Master_Plan_Volume_6 - Copy - Copy.docx | E11: Duplicate comparison; P13 content/XML screening
A12: SHIVANSH_PreAward_207_Activities_ProjectLibre_Import.xml | B12: d3f7199e9981a38001856c7fc4dfacadcc7158efe4310febc1c9040489b5bcb2 | C12: 1 | E12: Duplicate comparison; P13 content/XML screening
A13: SHIVANSH_EPC_Master_Plan_Volume_6 - Copy.docx | B13: 210c62c17a32f6b0545c512e9ae7d145c318845c51edd1ab2af106cd7ba3d79e | C13: 0 | D13: SHIVANSH_EPC_Master_Plan_Volume_6 - Copy - Copy.docx | E13: Duplicate comparison; P13 content/XML screening
A14: SOW & Bridge Report Combined - Copy - Copy.pdf | B14: 1dd8c329d410a7ea7f6b497d8c0fb230e23feaeabcd80964503bdb530236770a | C14: 4 | E14: Duplicate comparison; P13 content/XML screening
A15: SOW & Bridge Report Combined - Copy.pdf | B15: 1dd8c329d410a7ea7f6b497d8c0fb230e23feaeabcd80964503bdb530236770a | C15: 4 | D15: SOW & Bridge Report Combined - Copy - Copy.pdf | E15: Duplicate comparison; P13 content/XML screening
A16: SOW & Bridge Report Combined (3) - Copy - Copy.pdf | B16: 1dd8c329d410a7ea7f6b497d8c0fb230e23feaeabcd80964503bdb530236770a | C16: 4 | D16: SOW & Bridge Report Combined - Copy - Copy.pdf | E16: Duplicate comparison; P13 content/XML screening
A17: SOW & Bridge Report Combined (3) - Copy.pdf | B17: 1dd8c329d410a7ea7f6b497d8c0fb230e23feaeabcd80964503bdb530236770a | C17: 4 | D17: SOW & Bridge Report Combined - Copy - Copy.pdf | E17: Duplicate comparison; P13 content/XML screening
A18: SOW & Bridge Report Combined (3).pdf | B18: 1dd8c329d410a7ea7f6b497d8c0fb230e23feaeabcd80964503bdb530236770a | C18: 4 | D18: SOW & Bridge Report Combined - Copy - Copy.pdf | E18: Duplicate comparison; P13 content/XML screening
A19: SOW & Bridge Report Combined.pdf | B19: 1dd8c329d410a7ea7f6b497d8c0fb230e23feaeabcd80964503bdb530236770a | C19: 4 | D19: SOW & Bridge Report Combined - Copy - Copy.pdf | E19: Duplicate comparison; P13 content/XML screening
A20: Specification Combined - Copy - Copy.pdf | B20: fcb66cef439b04510b11d0225c2c7327e70a7aeaa8476651e9adc4329a5095eb | C20: 4 | E20: Duplicate comparison; P13 content/XML screening
A21: Specification Combined - Copy - Copy - Copy.pdf | B21: fcb66cef439b04510b11d0225c2c7327e70a7aeaa8476651e9adc4329a5095eb | C21: 4 | D21: Specification Combined - Copy - Copy.pdf | E21: Duplicate comparison; P13 content/XML screening
A22: Specification Combined - Copy.pdf | B22: fcb66cef439b04510b11d0225c2c7327e70a7aeaa8476651e9adc4329a5095eb | C22: 4 | D22: Specification Combined - Copy - Copy.pdf | E22: Duplicate comparison; P13 content/XML screening
A23: Specification Combined - Copy (2) - Copy.pdf | B23: fcb66cef439b04510b11d0225c2c7327e70a7aeaa8476651e9adc4329a5095eb | C23: 4 | D23: Specification Combined - Copy - Copy.pdf | E23: Duplicate comparison; P13 content/XML screening
A24: Specification Combined - Copy (2).pdf | B24: fcb66cef439b04510b11d0225c2c7327e70a7aeaa8476651e9adc4329a5095eb | C24: 4 | D24: Specification Combined - Copy - Copy.pdf | E24: Duplicate comparison; P13 content/XML screening
A25: TBOextension050526 - Copy - Copy - Copy.pdf | B25: 9b7cf7505a87a3743ad2da609f7cd2357ad0717a20aefae32c1baf4196876011 | C25: 1 | E25: Duplicate comparison; P13 content/XML screening
A26: Specification Combined.pdf | B26: fcb66cef439b04510b11d0225c2c7327e70a7aeaa8476651e9adc4329a5095eb | C26: 4 | D26: Specification Combined - Copy - Copy.pdf | E26: Duplicate comparison; P13 content/XML screening
A27: TBOextension050526 - Copy - Copy.pdf | B27: 9b7cf7505a87a3743ad2da609f7cd2357ad0717a20aefae32c1baf4196876011 | C27: 1 | D27: TBOextension050526 - Copy - Copy - Copy.pdf | E27: Duplicate comparison; P13 content/XML screening
A28: TBOextension050526 - Copy (2).pdf | B28: 9b7cf7505a87a3743ad2da609f7cd2357ad0717a20aefae32c1baf4196876011 | C28: 1 | D28: TBOextension050526 - Copy - Copy - Copy.pdf | E28: Duplicate comparison; P13 content/XML screening
A29: TBOextension050526 - Copy (2) - Copy.pdf | B29: 9b7cf7505a87a3743ad2da609f7cd2357ad0717a20aefae32c1baf4196876011 | C29: 1 | D29: TBOextension050526 - Copy - Copy - Copy.pdf | E29: Duplicate comparison; P13 content/XML screening
A30: TBOextension050526 - Copy.pdf | B30: 9b7cf7505a87a3743ad2da609f7cd2357ad0717a20aefae32c1baf4196876011 | C30: 1 | D30: TBOextension050526 - Copy - Copy - Copy.pdf | E30: Duplicate comparison; P13 content/XML screening
A31: TBOextension050526.pdf | B31: 9b7cf7505a87a3743ad2da609f7cd2357ad0717a20aefae32c1baf4196876011 | C31: 1 | D31: TBOextension050526 - Copy - Copy - Copy.pdf | E31: Duplicate comparison; P13 content/XML screening
A32: TBOextension090626 - Copy - Copy.pdf | B32: 916fdbeecc51c1c44bb20aa3cbc1a8ef3a246fbb0e7c38d605007f72d24021a1 | C32: 2 | E32: Duplicate comparison; P13 content/XML screening
A33: TBOextension090626 - Copy.pdf | B33: 916fdbeecc51c1c44bb20aa3cbc1a8ef3a246fbb0e7c38d605007f72d24021a1 | C33: 2 | D33: TBOextension090626 - Copy - Copy.pdf | E33: Duplicate comparison; P13 content/XML screening
A34: TBOextension090626 - Copy - Copy - Copy.pdf | B34: 916fdbeecc51c1c44bb20aa3cbc1a8ef3a246fbb0e7c38d605007f72d24021a1 | C34: 2 | D34: TBOextension090626 - Copy - Copy.pdf | E34: Duplicate comparison; P13 content/XML screening
A35: TBOextension090626.pdf | B35: 916fdbeecc51c1c44bb20aa3cbc1a8ef3a246fbb0e7c38d605007f72d24021a1 | C35: 2 | D35: TBOextension090626 - Copy - Copy.pdf | E35: Duplicate comparison; P13 content/XML screening
A36: TBOextension250526 - Copy - Copy - Copy.pdf | B36: c74098b236b0b059fe9cd539b814bf6838c586cd3a2701d63f41a0d579b7494b | C36: 1 | E36: Duplicate comparison; P13 content/XML screening
A37: TBOextension250526 - Copy - Copy.pdf | B37: c74098b236b0b059fe9cd539b814bf6838c586cd3a2701d63f41a0d579b7494b | C37: 1 | D37: TBOextension250526 - Copy - Copy - Copy.pdf | E37: Duplicate comparison; P13 content/XML screening
A38: TBOextension250526 - Copy.pdf | B38: c74098b236b0b059fe9cd539b814bf6838c586cd3a2701d63f41a0d579b7494b | C38: 1 | D38: TBOextension250526 - Copy - Copy - Copy.pdf | E38: Duplicate comparison; P13 content/XML screening
A39: TBOextension250526.pdf | B39: c74098b236b0b059fe9cd539b814bf6838c586cd3a2701d63f41a0d579b7494b | C39: 1 | D39: TBOextension250526 - Copy - Copy - Copy.pdf | E39: Duplicate comparison; P13 content/XML screening
A40: Technical_SCC - Copy - Copy.pdf | B40: c954759fb14588581784c894f9ffe949760a608217a75f73809b4eefa937ee17 | C40: 9 | E40: Duplicate comparison; P13 content/XML screening
...

Sheet Requirements
A1: ID | B1: Requirement topic | C1: Source | D1: Requirement | E1: Owner | F1: Verification evidence | G1: Status
A2: P9-01 | B2: Bid security | C2: Corrigendum.pdf p1 | D2: Any e-BG must be executed on NeSL before the tender closing deadline; later execution is liable to rejection. | E2: Treasury / Bid Manager | F2: Record portal execution timestamp and evidence; reconcile actual closing date with all extension notices. | G2: OPEN — source requirement; execution not evidenced
A3: P9-02 | B3: Bid validity | C3: Corrigendum_2.pdf pp1-2,5; Corrigendum_4.pdf p1; CQ_replies_BRRP.pdf pp2-3 | D3: Bid security extends 45 days beyond bid validity or extended validity. Bid validity is 120 days after opening of unpriced techno-contractual bids; do not anchor it to submission closing. | E3: Treasury / Contracts | F3: Use actual opening date; diarise bid and security expiry separately. Surety claim-period provisions remain distinct. | G3: OPEN — source requirement; execution not evidenced
A4: P9-03 | B4: Performance security | C4: Corrigendum_1_BRRP.pdf p1 | D4: The quoted ITB 28.1 option for 3% initial security plus 7% progressive deductions is deleted. | E4: Contracts / Finance | F4: Remove that financing assumption; reconcile remaining ITB 28.1, IFB and B-3 for governing amounts, submission and validity. Do not infer replacement wording from deletion alone. | G4: OPEN — source requirement; execution not evidenced
A5: P9-04 | B5: Supporting-company guarantees | C5: Corrigendum_2.pdf pp2-5 | D5: B-19/B-20/B-22 specified guarantee deadlines change from 15 to 30 days from NOA. Applicable supporting/JV guarantee provisions include delayed-submission recovery wording. | E5: Contracts / Treasury | F5: Set separate applicable-route milestones. Review 1.5% of performance-security amount per month or part-month recovery wording; do not apply indiscriminately to every guarantee. | G5: OPEN — source requirement; execution not evidenced
A6: P9-05 | B6: Setting out and changes | C6: Corrigendum_3.pdf p1, GCC 2.3.6 | D6: Modified column reinstates setting-out responsibility. Contractor corrects its positioning errors; company checking does not relieve it. Later company data/instructions after pre-engineering survey causing scope changes are dealt with under Clause 8.0. | E6: Survey / Engineering / Contracts | F6: Establish controlled datums, coordinates, survey acceptance and independent dimensional checks; preserve instruction/change evidence. This clause is not deleted. | G6: OPEN — source requirement; execution not evidenced
A7: P9-06 | B7: Domestic steel compliance | C7: Corrigendum_3.pdf pp1-8 | D7: DMI&SP policy reference changes to notification dated 17 December 2025, G.S.R.904(E). All bidders submit Form-1; item-specific Melt & Pour and domestic-value-addition provisions apply. | E7: Procurement / QA / Contracts | F7: Classify items under policy Appendix A/B and HS code. Obtain heat/mill origin records, Form-1, authorisations and applicable auditor certificates; maintain traceability. Do not confuse these policy appendices with tender appendices. | G7: OPEN — source requirement; execution not evidenced
A8: P9-07 | B8: MSE and local content | C8: CQ_replies_BRRP.pdf p5 | D8: ONGC reply says PPP-MSE exemption/purchase-preference benefits do not apply to this LSTK works tender. PP-MII is referred to ITB23.6.2(b). | E8: Bid / Procurement | F8: Remove assumed MSE EMD exemption; verify PP-MII separately, including current amendments. | G8: OPEN — source requirement; execution not evidenced
A9: P9-08 | B9: Bid content | C9: CQ_replies_BRRP.pdf p6 | D9: ONGC reply requires only BRS Part V-A with Quoted/Not Quoted confirmations in the unpriced bid; price manner follows the actual price format. | E9: Bid Manager | F9: Keep prices in the correct cover; reconcile all A-3 line items and BRS. This reply does not waive separate subcontractor commitment requirements. | G9: OPEN — source requirement; execution not evidenced
A10: P9-09 | B10: Tax and precedence | C10: CQ_replies_BRRP.pdf pp7-9 | D10: Beyond-12NM works are not declared tax-exempt: prevailing GST applies; offshore GSTIN may be used. SCC overrides GCC for conflicts; complete priority is referred to B-4. Liability reduction request was rejected. | E10: Tax / Contracts | F10: Prepare transaction-specific GST, customs and withholding matrix; use B-4 for full hierarchy. Do not adopt the bidder-proposed document hierarchy or 15% liability cap. | G10: OPEN — source requirement; execution not evidenced
A11: P9-10 | B11: Pre-bid and extension requests | C11: Corrigendum_1_BRRP.pdf p1; CQ_replies_BRRP.pdf pp7,9 | D11: Pre-bid conference was physical only, 8 April 2026. Six-week bid extension request was called premature at PBC stage. | E11: Document Control / Bid | F11: Record historical event; use issued extension notices for actual deadline. This reply is not a six-week extension grant. | G11: OPEN — source requirement; execution not evidenced
A12: P9-11 | B12: Integrity pact | C12: IP (1).pdf pp2,4-6; IP.pdf identical | D12: Disclose intermediaries and relevant transgressions, obtain subcontractor adoption undertakings, retain records for IEM access. Contractor pact duration extends 12 months beyond last payment; other bidders six months after award, subject to outstanding claims. | E12: Compliance / Contracts | F12: Maintain signed pact, partner/consortium signatures as applicable, declarations and subcontract flow-down; extend compliance retention beyond physical completion. No signed compliance evidence established by blank form. | G12: OPEN — source requirement; execution not evidenced
... A103: P13-13 | B103: Unclassified file | C103: ticket.pdf; unique-content extract | D103: Classify separately based on actual content. A personal/travel document does not change project technical or commercial scope merely because uploaded with tender documents. | E103: Workstream accountable owner | F103: Exclude unrelated personal information from shared project deliverables; do not treat a ticket as project award, approval or mobilisation evidence without a relevant explicit reference. | G103: Carry-forward action; requires actual evidence

Sheet Bridge MTO
A1: Bridge | B1: Work type | C1: New bridge MT | D1: Bridge strengthen MT | E1: New landing MT | F1: Landing strengthen MT | G1: Demolition MT | H1: Handrail m | I1: Grating m2 | J1: GI sheet m2 | K1: Construction MT | L1: Status
A2: ICW-ICG UD | B2: Strengthening | C2: 0 | D2: 19 | E2: 0 | F2: 30 | G2: 25 | H2: 110 | I2: 58 | J2: 273 | K2: 49 | L2: SOURCE TRANSCRIPTION; NOT PROCUREMENT BOM
A3: ICW-ICG LD | B3: New/replacement | C3: 57 | D3: 0 | E3: 65 | F3: 0 | G3: 1 | H3: 118 | I3: 88 | J3: 0 | K3: 122 | L3: SOURCE TRANSCRIPTION; NOT PROCUREMENT BOM
A4: ICG-ICP UD | B4: Strengthening | C4: 0 | D4: 86 | E4: 0 | F4: 30 | G4: 25 | H4: 93 | I4: 49 | J4: 419 | K4: 116 | L4: SOURCE TRANSCRIPTION; NOT PROCUREMENT BOM
A5: ICG-ICP LD | B5: New/replacement | C5: 115 | D5: 0 | E5: 45 | F5: 0 | G5: 1 | H5: 176 | I5: 132 | J5: 0 | K5: 160 | L5: SOURCE TRANSCRIPTION; NOT PROCUREMENT BOM
A6: BHS-SLQ | B6: Replacement/services | C6: 195 | D6: 0 | E6: 87 | F6: 0 | G6: 210 | H6: 88 | I6: 82 | J6: 332 | K6: 282 | L6: SOURCE TRANSCRIPTION; NOT PROCUREMENT BOM
A7: SLQ-WIS | B7: Strengthening | C7: 0 | D7: 61 | E7: 0 | F7: 30 | G7: 15 | H7: 98 | I7: 51 | J7: 0 | K7: 91 | L7: SOURCE TRANSCRIPTION; NOT PROCUREMENT BOM
A8: NQO-NQD | B8: Strengthening | C8: 0 | D8: 63 | E8: 0 | F8: 30 | G8: 25 | H8: 93 | I8: 58 | J8: 250 | K8: 93 | L8: SOURCE TRANSCRIPTION; NOT PROCUREMENT BOM
A9: WIN-NC | B9: Strengthening | C9: 0 | D9: 6 | E9: 0 | F9: 40 | G9: 10 | H9: 45 | I9: 29 | J9: 0 | K9: 46 | L9: SOURCE TRANSCRIPTION; NOT PROCUREMENT BOM
A10: SCA-SC1 | B10: Strengthening | C10: 0 | D10: 35 | E10: 0 | F10: 28 | G10: 15 | H10: 88 | I10: 55 | J10: 0 | K10: 63 | L10: SOURCE TRANSCRIPTION; NOT PROCUREMENT BOM
A11: SCA-SCF | B11: Strengthening | C11: 0 | D11: 91 | E11: 0 | F11: 28 | G11: 30 | H11: 257 | I11: 116 | J11: 0 | K11: 119 | L11: SOURCE TRANSCRIPTION; NOT PROCUREMENT BOM

Sheet MTO Reconciliation
A1: Item | B1: Printed total | C1: Sum source rows | D1: Difference | E1: Action
A2: New bridge MT | B2: 367 | C2: 367 | D2: 0 | E2: Verify released design
A3: Bridge strengthen MT | B3: 361 | C3: 361 | D3: 0 | E3: Verify released design
A4: New landing MT | B4: 197 | C4: 197 | D4: 0 | E4: Verify released design
A5: Landing strengthen MT | B5: 217 | C5: 216 | D5: 1 | E5: Resolve source discrepancy
A6: Structural MT | B6: 1142 | C6: 1141 | D6: 1 | E6: Resolve before purchase baseline
A7: Demolition MT | B7: 357 | C7: 357 | D7: 0 | E7: Verify removal allocations
A8: Handrail m | B8: 1168 | C8: 1166 | D8: 2 | E8: Resolve source discrepancy
A9: Grating m2 | B9: 719 | C9: 718 | D9: 1 | E9: Resolve source discrepancy
A10: GI sheeting m2 | B10: 1274 | C10: 1274 | D10: 0 | E10: Verify design areas

Sheet Design Basis
A1: Parameter | B1: Source criterion / query | C1: Reference | D1: Required resolution
A2: Design life | B2: New bridges25years | C2: CriteriaPartII p119 | D2: Confirm remaining/new component applicability
A3: Elastic modulus | B3: 210000MPa | C3: Criteria p66 | D3: Use approved material model
A4: Density | B4: 7850kg/m3 | C4: Criteria p66 | D4: Coatings/attachments/rigging separate
A5: Global walkway live load | B5: 250kg/m2 | C5: Criteria pp42–43 | D5: Do not replace local grating criteria
A6: Local grating load | B6: 500kg/m2 | C6: Criteria p70 | D6: Apply local design/approved combinations
A7: Clear walkway | B7: At least1.2m plus services allowance | C7: Criteria pp42–43 | D7: Verify actual service envelope
A8: Piping load allowance | B8: Operating/planned future plus20% as stated | C8: Criteria pp42–43 | D8: Resolve double-counting of future services
A9: Bearing system | B9: Pinned/hinged and sliding/PTFE-equivalent with guides | C9: Criteria pp42–43 | D9: Resolve BHS fixed/sliding source conflict
A10: Movement/thrust | B10: 150% specified platform translations/thrust basis | C10: Criteria pp42–43 | D10: Use verified platform movements and reactions
A11: Deflection | B11: Vertical L/400;lateral wind L/500 | C11: Criteria p86 | D11: Verify governing span and load case
A12: Camber | B12: Compensate DL; studies and generic L/200 conflict | C12: Criteria/source bridge studies | D12: Resolve profile rather than assume L/200
... A16: Geometry reference | B16: Tender dimensions indicative; survey required | C16: Combined1 GA notes; A9 | D16: Do not adopt study span as surveyed geometry

Sheet Engineering DCI
A1: Proposed document ID | B1: Bridge/platform | C1: Deliverable | D1: Mother/input dependency | E1: Document category A/I/R | F1: Review disposition A/B/C | G1: Status | H1: Source/evidence | I1: Owner
A2: SHV-B01-DB-R0 | B2: ICW-ICG UD | C2: Bridge-specific design basis | D2: Survey and controlling criteria | E2: TBC in project DCI/MCI | F2: TBC | G2: NOT SUBMITTED | H2: No signed approval evidence | I2: Engineering
A3: SHV-B01-SUR-R0 | B3: ICW-ICG UD | C3: Pre-engineering/condition survey dossier | D3: Access, survey and NDT | E3: TBC in project DCI/MCI | F3: TBC | G3: NOT SUBMITTED | H3: No signed approval evidence | I3: Engineering
A4: SHV-B01-ANA-R0 | B4: ICW-ICG UD | C4: Global bridge/serviceability/fatigue/VIV analysis | D4: DB/SUR accepted | E4: TBC in project DCI/MCI | F4: TBC | G4: NOT SUBMITTED | H4: No signed approval evidence | I4: Engineering
A5: SHV-B01-PRE-R0 | B5: ICW-ICG UD | C5: Preservice lift/transport/temporary-stage analysis | D5: Module envelope and vessel inputs | E5: TBC in project DCI/MCI | F5: TBC | G5: NOT SUBMITTED | H5: No signed approval evidence | I5: Engineering
A6: SHV-B01-SUP-R0 | B6: ICW-ICG UD | C6: Landing/deck/support and interface reaction report | D6: Bridge/piping reactions | E6: TBC in project DCI/MCI | F6: TBC | G6: NOT SUBMITTED | H6: No signed approval evidence | I6: Engineering
A7: SHV-B01-JNT-R0 | B7: ICW-ICG UD | C7: Connection/member/bearing check report | D7: Global forces and verified materials | E7: TBC in project DCI/MCI | F7: TBC | G7: NOT SUBMITTED | H7: No signed approval evidence | I7: Engineering
A8: SHV-B01-GA-R0 | B8: ICW-ICG UD | C8: General arrangement and geometry details | D8: Accepted mother analysis | E8: TBC in project DCI/MCI | F8: TBC | G8: NOT SUBMITTED | H8: No signed approval evidence | I8: Engineering
A9: SHV-B01-SHOP-R0 | B9: ICW-ICG UD | C9: Shop member, weld, joint and erection details | D9: GA and checked connection calculations | E9: TBC in project DCI/MCI | F9: TBC | G9: NOT SUBMITTED | H9: No signed approval evidence | I9: Engineering
A10: SHV-B01-BRG-R0 | B10: ICW-ICG UD | C10: Bearing, guides, setting and restraints | D10: Movement/thrust and temperature envelope | E10: TBC in project DCI/MCI | F10: TBC | G10: NOT SUBMITTED | H10: No signed approval evidence | I10: Engineering
A11: SHV-B01-TMP-R0 | B11: ICW-ICG UD | C11: Temporary supports/stability and strengthening details | D11: Stage analyses and surveyed condition | E11: TBC in project DCI/MCI | F11: TBC | G11: NOT SUBMITTED | H11: No signed approval evidence | I11: Engineering
A12: SHV-B01-LFT-R0 | B12: ICW-ICG UD | C12: Lift/rigging/padeye/loadout procedure and drawings | D12: PRE/vessel/weight/COG | E12: TBC in project DCI/MCI | F12: TBC | G12: NOT SUBMITTED | H12: No signed approval evidence | I12: Engineering
... A184: SHV-PLAT-SCF | B184: SCF | C184: Local deck inplace assessment | D184: Verified geometry + reactions | E184: TBC | F184: TBC | G184: NOT SUBMITTED | H184: Combined1 Annexure1 p2 | I184: Structural

Sheet Tender GA Mapping
A1: Bridge | B1: Source drawing | C1: Source PDF page | D1: Use | E1: Open issue
A2: ICW–ICG LD | B2: B774-101-83-43-0001 | C2: Combined1 p27 | D2: Tender GA/source detailing | E2: RegisterRev0 vs titleRevA; survey verification
A3: ICP–ICG LD | B3: B774-102-83-43-0001 sheets1–2 | C3: Combined1 pp31–32 | D3: Tender GA/source detailing | E3: Mother calculation and survey required
A4: BHS–SLQ | B4: B774-103-83-43-0001 | C4: Combined1 p36 | D4: Tender replacement GA | E4: Bearing orientation/camber/services resolution
A5: BHS–SLQ old removal | B5: B774-103-83-43-0006 | C5: Combined1 p41 | D5: Tender removal reference | E5: Approved service transfer/temporary stability required
A6: All bridges | B6: MTO Drawings IRT and Combined1 register | C6: MTOIRT34pages; Combined1 pp3–5 | D6: Strengthening/landing/general detail sources | E6: Map34entry updated register vs older38 before omission decisions

Sheet Procurement 25
A1: Package | B1: Scope | C1: Engineering input | D1: Quantity/compliance basis | E1: Owner | F1: Price | G1: Supplier date | H1: Release gate | I1: Status
A2: STEEL-B01 | B2: ICW-ICG UD structural material | C2: B01-MTO/AFC + PS | D2: Verified member/plate BOM; grade; heat/MTC/origin | E2: Procurement | F2: UNPRICED | G2: UNCONFIRMED | H2: PS/material inspection release | I2: OPEN
A3: STEEL-B02 | B3: ICW-ICG LD structural material | C3: B02-MTO/AFC + PS | D3: Verified member/plate BOM; grade; heat/MTC/origin | E3: Procurement | F3: UNPRICED | G3: UNCONFIRMED | H3: PS/material inspection release | I3: OPEN
A4: STEEL-B03 | B4: ICG-ICP UD structural material | C4: B03-MTO/AFC + PS | D4: Verified member/plate BOM; grade; heat/MTC/origin | E4: Procurement | F4: UNPRICED | G4: UNCONFIRMED | H4: PS/material inspection release | I4: OPEN
A5: STEEL-B04 | B5: ICG-ICP LD structural material | C5: B04-MTO/AFC + PS | D5: Verified member/plate BOM; grade; heat/MTC/origin | E5: Procurement | F5: UNPRICED | G5: UNCONFIRMED | H5: PS/material inspection release | I5: OPEN
A6: STEEL-B05 | B6: BHS-SLQ structural material | C6: B05-MTO/AFC + PS | D6: Verified member/plate BOM; grade; heat/MTC/origin | E6: Procurement | F6: UNPRICED | G6: UNCONFIRMED | H6: PS/material inspection release | I6: OPEN
A7: STEEL-B06 | B7: SLQ-WIS structural material | C7: B06-MTO/AFC + PS | D7: Verified member/plate BOM; grade; heat/MTC/origin | E7: Procurement | F7: UNPRICED | G7: UNCONFIRMED | H7: PS/material inspection release | I7: OPEN
A8: STEEL-B07 | B8: NQO-NQD structural material | C8: B07-MTO/AFC + PS | D8: Verified member/plate BOM; grade; heat/MTC/origin | E8: Procurement | F8: UNPRICED | G8: UNCONFIRMED | H8: PS/material inspection release | I8: OPEN
A9: STEEL-B08 | B9: WIN-NC structural material | C9: B08-MTO/AFC + PS | D9: Verified member/plate BOM; grade; heat/MTC/origin | E9: Procurement | F9: UNPRICED | G9: UNCONFIRMED | H9: PS/material inspection release | I9: OPEN
A10: STEEL-B09 | B10: SCA-SC1 structural material | C10: B09-MTO/AFC + PS | D10: Verified member/plate BOM; grade; heat/MTC/origin | E10: Procurement | F10: UNPRICED | G10: UNCONFIRMED | H10: PS/material inspection release | I10: OPEN
A11: STEEL-B10 | B11: SCA-SCF structural material | C11: B10-MTO/AFC + PS | D11: Verified member/plate BOM; grade; heat/MTC/origin | E11: Procurement | F11: UNPRICED | G11: UNCONFIRMED | H11: PS/material inspection release | I11: OPEN
A12: BEAR | B12: Bearings, sliding interfaces and guides | C12: Applicable approved requisition/PS/service scope | D12: Quantity/specification/applicability to be confirmed | E12: Engineering | F12: UNPRICED | G12: UNCONFIRMED | H12: Applicable QA/company readiness release | I12: OPEN
... A26: TRAY | B26: Cable trays and support steel interfaces | C26: Applicable approved requisition/PS/service scope | D26: Quantity/specification/applicability to be confirmed | E26: Electrical | F26: UNPRICED | G26: UNCONFIRMED | H26: Applicable QA/company readiness release | I26: OPEN

Sheet Workpack Readiness
A1: IWP | B1: Bridge | C1: Task | D1: Unit | E1: Verified quantity | F1: Evidence index | G1: AFC | H1: Material | I1: Access PTW | J1: Crew tools | K1: ITP QA | L1: Marine SIMOPS | M1: Method | N1: Company release | O1: Readiness screen | P1: Acceptance evidence | Q1: Authorised release
A2: B01-SUR | B2: ICW-ICG UD | C2: Survey and verified access | D2: survey pack | O2: =IF(COUNTIF(G2:N2,"YES")=8,"VERIFY EVIDENCE","HOLD") | P2: Accepted geometry/NDT | Q2: NOT RELEASED
A3: B01-ENG | B3: ICW-ICG UD | C3: Design/detail/MTO release | D3: document pack | O3: =IF(COUNTIF(G3:N3,"YES")=8,"VERIFY EVIDENCE","HOLD") | P3: Checked analysis and AFC index | Q3: NOT RELEASED
A4: B01-MAT | B4: ICW-ICG UD | C4: Material and traceability receipt | D4: BOM item | O4: =IF(COUNTIF(G4:N4,"YES")=8,"VERIFY EVIDENCE","HOLD") | P4: PS/MTC/origin and TPI release | Q4: NOT RELEASED
A5: B01-FAB | B5: ICW-ICG UD | C5: Fabrication and connection work | D5: member/weld/BOM | O5: =IF(COUNTIF(G5:N5,"YES")=8,"VERIFY EVIDENCE","HOLD") | P5: WPS/welder/NDT/dimension records | Q5: NOT RELEASED
A6: B01-COAT | B6: ICW-ICG UD | C6: Preparation/coating/curing | D6: m2 by system | O6: =IF(COUNTIF(G6:N6,"YES")=8,"VERIFY EVIDENCE","HOLD") | P6: Accepted surface/environment/DFT records | Q6: NOT RELEASED
A7: B01-LOAD | B7: ICW-ICG UD | C7: Loadout/transport/receipt | D7: module | O7: =IF(COUNTIF(G7:N7,"YES")=8,"VERIFY EVIDENCE","HOLD") | P7: Weight/COG/rigging/sea-fastening approval | Q7: NOT RELEASED
A8: B01-SUP | B8: ICW-ICG UD | C8: Support strengthening and temporary stability | D8: member/joint | O8: =IF(COUNTIF(G8:N8,"YES")=8,"VERIFY EVIDENCE","HOLD") | P8: Approved stage analysis and inspected installation | Q8: NOT RELEASED
A9: B01-INST | B9: ICW-ICG UD | C9: Bridge installation/strengthening | D9: member/module | O9: =IF(COUNTIF(G9:N9,"YES")=8,"VERIFY EVIDENCE","HOLD") | P9: PTW and engineered method accepted | Q9: NOT RELEASED
A10: B01-SERV | B10: ICW-ICG UD | C10: Service transfer/testing | D10: line/circuit/system | O10: =IF(COUNTIF(G10:N10,"YES")=8,"VERIFY EVIDENCE","HOLD") | P10: Isolation/test boundary/operations acceptance | Q10: NOT RELEASED
A11: B01-DEM | B11: ICW-ICG UD | C11: Removal/scrap backload | D11: item/MT | O11: =IF(COUNTIF(G11:N11,"YES")=8,"VERIFY EVIDENCE","HOLD") | P11: Accepted support/service sequence and disposal receipt | Q11: NOT RELEASED
A12: B01-PUNCH | B12: ICW-ICG UD | C12: Inspection/punch closure | D12: punch item | O12: =IF(COUNTIF(G12:N12,"YES")=8,"VERIFY EVIDENCE","HOLD") | P12: Accepted ITR and blocking-punch closure | Q12: NOT RELEASED
A13: B01-TURN | B13: ICW-ICG UD | C13: As-built/turnover | D13: dossier | O13: =IF(COUNTIF(G13:N13,"YES")=8,"VERIFY EVIDENCE","HOLD") | P13: Accepted bridge/system completion | Q13: NOT RELEASED
... A121: B10-TURN | B121: SCA-SCF | C121: As-built/turnover | D121: dossier | O121: =IF(COUNTIF(G121:N121,"YES")=8,"VERIFY EVIDENCE","HOLD") | P121: Accepted bridge/system completion | Q121: NOT RELEASED

Sheet Resource Commitments
A1: Resource | B1: Scenario assumption | C1: Actual capacity | D1: Availability dates | E1: Evidence | F1: Owner | G1: Status
A2: Design teams | B2: Parallel ten-bridge design assumed; loading not modelled | F2: Engineering | G2: UNVERIFIED
A3: Fabrication | B3: 2capacity-one bay chains at4MT/productive bay-day | F3: Fabrication | G3: UNVERIFIED
A4: Coating | B4: 1capacity-one cell;10yard-days/package | F4: Coating | G4: UNVERIFIED
A5: NDT | B5: No finite staffing capacity modelled | F5: QA | G5: UNVERIFIED
A6: Strengthening | B6: 3capacity-one crew chains;4MT/crew-day allowance | F6: Construction | G6: UNVERIFIED
A7: Heavy lift | B7: 1capacity-one new-bridge installation chain | F7: Marine | G7: UNVERIFIED
A8: Cargo | B8: 1capacity-one transport/demob chain | F8: Logistics | G8: UNVERIFIED
A9: Services | B9: 1capacity-one transfer/test team | F9: Commissioning | G9: UNVERIFIED
A10: Removal | B10: 1capacity-one removal team | F10: Construction | G10: UNVERIFIED
A11: Survey | B11: 1spread for common field survey | F11: Survey | G11: UNVERIFIED
A12: Accommodation | B12: Minimum60special-personnel requirement; totalPOB not proven | F12: Marine | G12: UNVERIFIED

Sheet Schedule 285
A1: ID | B1: Bridge | C1: Activity | D1: Duration | E1: Calendar | F1: Predecessors | G1: Resource | H1: Owner | I1: ES | J1: EF exclusive | K1: LS | L1: LF exclusive | M1: Float calendar days | N1: Basis | O1: Status
A2: START | B2: COMMON | C2: Assumed commencement — scenario only | D2: 0 | E2: ALL | H2: Contracts | I2: 2026-11-01 | J2: 2026-11-01 | K2: 2026-11-02 | L2: 2026-11-02 | M2: 1 | N2: 1Nov2026 assumed; actual NOA unconfirmed | O2: PROPOSED / NOT APPROVED
A3: G01 | B3: COMMON | C3: Contract/amendment matrix and scope reconciliation | D3: 5 | E3: OFFICE | F3: START | H3: Contracts | I3: 2026-11-02 | J3: 2026-11-07 | K3: 2026-11-02 | L3: 2026-11-09 | M3: 0 | N3: Proposed allowance; replace with verified inputs | O3: PROPOSED / NOT APPROVED
A4: G02 | B4: COMMON | C4: Survey permits, access and mobilisation preparation | D4: 10 | E4: OFFICE | F4: G01 | H4: Survey / Operations | I4: 2026-11-09 | J4: 2026-11-21 | K4: 2026-11-09 | L4: 2026-11-22 | M4: 0 | N4: Proposed allowance; replace with verified inputs | O4: PROPOSED / NOT APPROVED
A5: G03 | B5: COMMON | C5: Pre-engineering survey campaign | D5: 15 | E5: OFF | F5: G02;D-SURV | G5: Survey spread | H5: Survey | I5: 2026-11-21 | J5: 2026-12-06 | K5: 2026-11-22 | L5: 2026-12-07 | M5: 1 | N5: Proposed allowance; replace with verified inputs | O5: PROPOSED / NOT APPROVED
A6: G04 | B6: COMMON | C6: Survey reports, geometry/condition reconciliation | D6: 5 | E6: OFFICE | F6: G03 | H6: Engineering | I6: 2026-12-07 | J6: 2026-12-12 | K6: 2026-12-07 | L6: 2026-12-14 | M6: 0 | N6: Proposed allowance; replace with verified inputs | O6: PROPOSED / NOT APPROVED
A7: G05 | B7: COMMON | C7: Survey/basis review and comment closure allowance | D7: 10 | E7: OFFICE | F7: G04 | H7: Engineering | I7: 2026-12-14 | J7: 2026-12-26 | K7: 2026-12-14 | L7: 2026-12-28 | M7: 0 | N7: Proposed allowance; replace with verified inputs | O7: PROPOSED / NOT APPROVED
A8: P-BEAR | B8: COMMON | C8: Bearings, sliding interfaces and guides — requisition/technical scope | D8: 5 | E8: OFFICE | F8: G05 | H8: Engineering | I8: 2026-12-28 | J8: 2027-01-02 | K8: 2027-11-05 | L8: 2027-11-12 | M8: 312 | N8: Proposed allowance; replace with verified inputs | O8: PROPOSED / NOT APPROVED
A9: R-BEAR | B9: COMMON | C9: Bearings, sliding interfaces and guides — bid/PS review allowance | D9: 10 | E9: OFFICE | F9: P-BEAR | H9: Engineering | I9: 2027-01-04 | J9: 2027-01-16 | K9: 2027-11-12 | L9: 2027-11-26 | M9: 312 | N9: Proposed allowance; replace with verified inputs | O9: PROPOSED / NOT APPROVED
A10: D-BEAR | B10: COMMON | C10: Bearings, sliding interfaces and guides — delivery/readiness | D10: 35 | E10: ALL | F10: R-BEAR | H10: Engineering | I10: 2027-01-16 | J10: 2027-02-20 | K10: 2027-11-26 | L10: 2027-12-31 | M10: 314 | N10: Unverified vendor/service lead-time allowance; no quote or commitment | O10: PROPOSED / NOT APPROVED
A11: P-GRAT | B11: COMMON | C11: Grating, handrail and GI sheet supply — requisition/technical scope | D11: 5 | E11: OFFICE | F11: G05 | H11: Procurement | I11: 2026-12-28 | J11: 2027-01-02 | K11: 2027-11-05 | L11: 2027-11-12 | M11: 312 | N11: Proposed allowance; replace with verified inputs | O11: PROPOSED / NOT APPROVED
A12: R-GRAT | B12: COMMON | C12: Grating, handrail and GI sheet supply — bid/PS review allowance | D12: 10 | E12: OFFICE | F12: P-GRAT | H12: Procurement | I12: 2027-01-04 | J12: 2027-01-16 | K12: 2027-11-12 | L12: 2027-11-26 | M12: 312 | N12: Proposed allowance; replace with verified inputs | O12: PROPOSED / NOT APPROVED
A13: D-GRAT | B13: COMMON | C13: Grating, handrail and GI sheet supply — delivery/readiness | D13: 35 | E13: ALL | F13: R-GRAT | H13: Procurement | I13: 2027-01-16 | J13: 2027-02-20 | K13: 2027-11-26 | L13: 2027-12-31 | M13: 314 | N13: Unverified vendor/service lead-time allowance; no quote or commitment | O13: PROPOSED / NOT APPROVED
A14: P-PIPE | B14: COMMON | C14: Piping tie-ins, fittings and supports — requisition/technical scope | D14: 5 | E14: OFFICE | F14: G05 | H14: Piping | I14: 2026-12-28 | J14: 2027-01-02 | K14: 2027-11-09 | L14: 2027-11-16 | M14: 316 | N14: Proposed allowance; replace with verified inputs | O14: PROPOSED / NOT APPROVED
A15: R-PIPE | B15: COMMON | C15: Piping tie-ins, fittings and supports — bid/PS review allowance | D15: 10 | E15: OFFICE | F15: P-PIPE | H15: Piping | I15: 2027-01-04 | J15: 2027-01-16 | K15: 2027-11-16 | L15: 2027-11-30 | M15: 316 | N15: Proposed allowance; replace with verified inputs | O15: PROPOSED / NOT APPROVED
A16: D-PIPE | B16: COMMON | C16: Piping tie-ins, fittings and supports — delivery/readiness | D16: 45 | E16: ALL | F16: R-PIPE | H16: Piping | I16: 2027-01-16 | J16: 2027-03-02 | K16: 2027-11-30 | L16: 2028-01-14 | M16: 318 | N16: Unverified vendor/service lead-time allowance; no quote or commitment | O16: PROPOSED / NOT APPROVED
A17: P-ELEC | B17: COMMON | C17: Electrical materials and bonding — requisition/technical scope | D17: 5 | E17: OFFICE | F17: G05 | H17: Electrical | I17: 2026-12-28 | J17: 2027-01-02 | K17: 2027-11-15 | L17: 2027-11-22 | M17: 322 | N17: Proposed allowance; replace with verified inputs | O17: PROPOSED / NOT APPROVED
... A63: B05-MAT | B63: BHS-SLQ | C63: Mill production, inspection and steel delivery | D63: 45 | E63: ALL | F63: B05-PO | H63: Procurement | I63: 2027-04-03 | J63: 2027-05-18 | K63: 2027-04-03 | L63: 2027-05-18 | M63: 0 | N63: Unquoted45calendar-day placeholder; origin, mill capacity and transport unresolved | O63: PROPOSED / NOT APPROVED
A64: B05-FAB | B64: BHS-SLQ | C64: Fit-up, welding and dimensional control | D64: 71 | E64: YARD | F64: B05-MAT;D-NDT;D-TPI | G64: Fabrication line 1 | H64: Fabrication | I64: 2027-05-18 | J64: 2027-08-08 | K64: 2027-05-18 | L64: 2027-08-09 | M64: 0 | N64: Assumed4MT per productive bay-day; includes aggregate steel, not validated shop productivity | O64: PROPOSED / NOT APPROVED
A65: B05-NDT | B65: BHS-SLQ | C65: NDT, repair allowance and dimensional release | D65: 6 | E65: YARD | F65: B05-FAB | H65: QA | I65: 2027-08-09 | J65: 2027-08-15 | K65: 2027-09-16 | L65: 2027-09-23 | M65: 38 | N65: Proposed allowance; replace with verified inputs | O65: PROPOSED / NOT APPROVED
A66: B05-COA | B66: BHS-SLQ | C66: Surface preparation, coating and curing allowance | D66: 10 | E66: YARD | F66: B05-NDT;D-COAT | G66: Coating cell | H66: Coating | I66: 2027-08-16 | J66: 2027-08-27 | K66: 2027-09-23 | L66: 2027-10-05 | M66: 38 | N66: Proposed allowance; replace with verified inputs | O66: PROPOSED / NOT APPROVED
A67: B05-REL | B67: BHS-SLQ | C67: Trial fit, verified weight/COG and loadout release | D67: 5 | E67: YARD | F67: B05-COA | H67: QA / Marine | I67: 2027-08-27 | J67: 2027-09-02 | K67: 2027-11-19 | L67: 2027-11-25 | M67: 84 | N67: Proposed allowance; replace with verified inputs | O67: PROPOSED / NOT APPROVED
A68: B05-TRN | B68: BHS-SLQ | C68: Loadout, transport and offshore receipt | D68: 3 | E68: OFF | F68: B05-REL;D-CARGO | G68: Cargo spread | H68: Logistics | I68: 2027-10-16 | J68: 2027-10-19 | K68: 2027-11-25 | L68: 2027-11-28 | M68: 40 | N68: Proposed allowance; replace with verified inputs | O68: PROPOSED / NOT APPROVED
A69: B05-PRE | B69: BHS-SLQ | C69: PTW, access, SIMOPS and work-front readiness | D69: 3 | E69: OFF | F69: B05-TRN;D-SCAF;D-PPE | H69: Construction | I69: 2027-10-19 | J69: 2027-10-22 | K69: 2027-11-28 | L69: 2027-12-01 | M69: 40 | N69: Proposed allowance; replace with verified inputs | O69: PROPOSED / NOT APPROVED
A70: B05-STR | B70: BHS-SLQ | C70: Landing/platform pre-install strengthening | D70: 22 | E70: OFF | F70: B05-PRE | G70: Strength crew 1 | H70: Construction | I70: 2027-10-22 | J70: 2027-11-13 | K70: 2027-12-01 | L70: 2027-12-23 | M70: 40 | N70: Proposed4MT/crew-day; actual weld/access quantities not validated | O70: PROPOSED / NOT APPROVED
A71: B05-INS | B71: BHS-SLQ | C71: New bridge installation | D71: 7 | E71: OFF | F71: B05-STR;D-MAR;D-BEAR;D-GRAT | G71: Heavy-lift spread | H71: Marine / Construction | I71: 2027-11-13 | J71: 2027-11-20 | K71: 2028-01-03 | L71: 2028-01-10 | M71: 51 | N71: Aggregate planning allowance; engineered lifts and temporary stability required | O71: PROPOSED / NOT APPROVED
A72: B05-SRV | B72: BHS-SLQ | C72: Services transfer, test and accepted reinstatement | D72: 5 | E72: OFF | F72: B05-INS;D-PIPE;D-ELEC;D-INST;D-TRAY | G72: Service transfer team | H72: Commissioning | I72: 2027-11-20 | J72: 2027-11-25 | K72: 2028-01-14 | L72: 2028-01-19 | M72: 55 | N72: Proposed allowance; replace with verified inputs | O72: PROPOSED / NOT APPROVED
A73: B05-DEM | B73: BHS-SLQ | C73: Engineered demolition/removal and scrap backload | D73: 14 | E73: OFF | F73: B05-SRV | G73: Removal team | H73: Construction | I73: 2027-11-25 | J73: 2027-12-09 | K73: 2028-02-03 | L73: 2028-02-17 | M73: 70 | N73: Proposed15MT/day allowance; BHS sequence after safe new service transfer, subject to approved method | O73: PROPOSED / NOT APPROVED
A74: B05-PUN | B74: BHS-SLQ | C74: Inspection, touch-up and offshore punch closure | D74: 3 | E74: OFF | F74: B05-DEM | H74: QA / Commissioning | I74: 2027-12-09 | J74: 2027-12-12 | K74: 2028-03-06 | L74: 2028-03-09 | M74: 88 | N74: Proposed allowance; replace with verified inputs | O74: PROPOSED / NOT APPROVED
